<?xml version="1.0"?>

<robot name="betabot">

  <link name='chassis'>
    <pose>0 0 0.1 0 0 0</pose>

    <inertial>
      <mass value="15.0"/>
      <origin xyz="0.0 0 0.1" rpy=" 0 0 0"/>
      <inertia
          ixx="0.1" ixy="0" ixz="0"
          iyy="0.1" iyz="0"
          izz="0.1"
      />
    </inertial>

    <collision name='collision'>
      <geometry>
        <box size=".2 .2 .4"/>
      </geometry>
    </collision>

    <visual name='chassis_visual'>
      <origin xyz="0 0 0.1" rpy=" 0 0 0"/>
      <geometry>
        <box size=".2 .2 .4"/>
      </geometry>
    </visual>

    <collision name='head_collision'>
      <origin xyz="-0.15 0 -0.05" rpy=" 0 0 0"/>
      <geometry>
        <sphere radius="0.1"/>
      </geometry>
    </collision>

    <visual name='head_visual'>
      <origin xyz="-0.15 0 -0.05" rpy=" 0 0 0"/>
      <geometry>
        <sphere radius="0.1"/>
      </geometry>
    </visual>

  </link>


  <link name="left_wheel">
    <collision name="collision">
      <origin xyz="0 0 0" rpy="0 1.5707 1.5707"/>
      <geometry>
        <cylinder radius="0.2" length="0.05"/>
      </geometry>
    </collision>
    <visual name="left_wheel_visual">
      <origin xyz="0 0 0" rpy="0 1.5707 1.5707"/>
      <geometry>
        <cylinder radius="0.2" length="0.05"/>
      </geometry>
    </visual>
    <inertial>
      <origin xyz="0 0 0" rpy="0 1.5707 1.5707"/>
      <mass value="5"/>
      <inertia
        ixx=".1" ixy="0.0" ixz="0.0"
        iyy=".1" iyz="0.0"
        izz=".1"/>
    </inertial>
  </link>

  <link name="right_wheel">
    <collision name="collision">
      <origin xyz="0 0 0" rpy="0 1.5707 1.5707"/>
      <geometry>
        <cylinder radius="0.2" length="0.05"/>
      </geometry>
    </collision>
    <visual name="right_wheel_visual">
      <origin xyz="0 0 0" rpy="0 1.5707 1.5707"/>
      <geometry>
        <cylinder radius="0.2" length="0.05"/>
      </geometry>
    </visual>
    <inertial>
      <origin xyz="0 0 0" rpy="0 1.5707 1.5707"/>
      <mass value="5"/>
      <inertia
        ixx=".1" ixy="0.0" ixz="0.0"
        iyy=".1" iyz="0.0"
        izz=".1"/>
    </inertial>
  </link>


  <joint type="continuous" name="left_wheel_hinge">
    <origin xyz="0 0.15 0" rpy="0 0 0"/>
    <child link="left_wheel"/>
    <parent link="chassis"/>
    <axis xyz="0 1 0" rpy="0 0 0"/>
    <limit effort="10000" velocity="1000"/>
    <joint_properties damping="1.0" friction="1.0"/>
  </joint>

  <joint type="continuous" name="right_wheel_hinge">
    <origin xyz="0 -0.15 0" rpy="0 0 0"/>
    <child link="right_wheel"/>
    <parent link="chassis"/>
    <axis xyz="0 1 0" rpy="0 0 0"/>
    <limit effort="10000" velocity="1000"/>
    <joint_properties damping="1.0" friction="1.0"/>
  </joint>

</robot>

