<?xml version="1.0"?>

<robot name="betabot">

  <link name='chassis'>
    <pose>0 0 0 0 0 0</pose>
    <inertial>
      <mass value="1"/>
      <origin xyz="0.0 0 0" rpy=" 0 0 0"/>
      <inertia
          ixx="0.1" ixy="0" ixz="0"
          iyy="0.1" iyz="0"
          izz="0.1"
      />
    </inertial>
    <collision name='collision'>
      <origin xyz="0 0 0" rpy="0 0 0"/>
      <geometry>
        <mesh filename="body.stl" scale="0.01 0.01 0.01" name="body" />
      </geometry>
    </collision>
    <visual name='chassis_visual'>
      <origin xyz="0 0 0" rpy="0 0 0"/>
      <geometry>
        <mesh filename="body.stl" scale="0.01 0.01 0.01" name="body" />
      </geometry>
      <material name="white">
        <color rgba="1 1 1 1"/>
      </material>
    </visual>
  </link>

  <link name="left_foot">
    <collision name="collision">
      <origin xyz="0 0 0" rpy="0 0 0"/>
      <geometry>
        <mesh filename="left_foot.stl" scale="0.01 0.01 0.01" name="left_foot" />
      </geometry>
    </collision>
    <visual name="left_foot_visual">
      <origin xyz="0 0 0" rpy="0 0 0"/>
      <geometry>
        <mesh filename="left_foot.stl" scale="0.01 0.01 0.01" name="left_foot" />
      </geometry>
      <material name="foot">
        <color rgba="0.1 0.1 0.9 0.8"/>
      </material>
    </visual>
    <inertial>
      <origin xyz="0 0 0" rpy="0 0 0"/>
      <mass value="0.1"/>
      <inertia
        ixx="0.0" ixy="0.0" ixz="0.0"
        iyy="0.0" iyz="0.0"
        izz="0.0"/>
    </inertial>
  </link>

  <link name="right_foot">
    <collision name="collision">
      <origin xyz="0 0 0" rpy="0 0 0"/>
      <geometry>
        <mesh filename="right_foot.stl" scale="0.01 0.01 0.01" name="right_foot" />
      </geometry>
    </collision>
    <visual name="right_foot_visual">
      <origin xyz="0 0 0" rpy="0 0 0"/>
      <geometry>
        <mesh filename="right_foot.stl" scale="0.01 0.01 0.01" name="right_foot" />
      </geometry>
      <material name="foot">
      </material>
    </visual>
    <inertial>
      <origin xyz="0 0 0" rpy="0 0 0"/>
      <mass value="0.1"/>
      <inertia
        ixx="0.0" ixy="0.0" ixz="0.0"
        iyy="0.0" iyz="0.0"
        izz="0.0"/>
    </inertial>
  </link>

  <link name="right_motor">
    <collision name="collision">
      <origin xyz="0 0 0" rpy="0 0 0"/>
      <geometry>
        <mesh filename="right_motor.stl" scale="0.01 0.01 0.01" name="right_motor" />
      </geometry>
    </collision>
    <visual name="right_motor_visual">
      <origin xyz="0 0 0" rpy="0 0 0"/>
      <geometry>
        <mesh filename="right_motor.stl" scale="0.01 0.01 0.01" name="right_motor" />
      </geometry>
      <material name="motor">
        <color rgba="0.6 0.6 0.6 0.8"/>
      </material>
    </visual>
    <inertial>
      <origin xyz="0 0 0" rpy="0 0 0"/>
      <mass value="0.8"/>
      <inertia
        ixx="0.0" ixy="0.0" ixz="0.0"
        iyy="0.0" iyz="0.0"
        izz="0.0"/>
    </inertial>
  </link>

  <link name="left_motor">
    <collision name="collision">
      <origin xyz="0 0 0" rpy="0 0 0"/>
      <geometry>
        <mesh filename="left_motor.stl" scale="0.01 0.01 0.01" name="left_motor" />
      </geometry>
    </collision>
    <visual name="right_motor_visual">
      <origin xyz="0 0 0" rpy="0 0 0"/>
      <geometry>
        <mesh filename="left_motor.stl" scale="0.01 0.01 0.01" name="left_motor" />
      </geometry>
      <material name="motor">
      </material>
    </visual>
    <inertial>
      <origin xyz="0 0 0" rpy="0 0 0"/>
      <mass value="0.8"/>
      <inertia
        ixx="0.0" ixy="0.0" ixz="0.0"
        iyy="0.0" iyz="0.0"
        izz="0.0"/>
    </inertial>
  </link>

  <link name="right_leg">
    <collision name="collision">
      <origin xyz="0 0 0" rpy="0 0 0"/>
      <geometry>
        <mesh filename="right_leg.stl" scale="0.01 0.01 0.01" name="right_leg" />
      </geometry>
    </collision>
    <visual name="right_leg_visual">
      <origin xyz="0 0 0" rpy="0 0 0"/>
      <geometry>
        <mesh filename="right_leg.stl" scale="0.01 0.01 0.01" name="right_leg" />
      </geometry>
      <material name="leg">
        <color rgba="0.3 0.3 0.2 0.1"/>
      </material>
    </visual>
    <inertial>
      <origin xyz="0 0 0" rpy="0 0 0"/>
      <mass value="0.1"/>
      <inertia
        ixx="0.0" ixy="0.0" ixz="0.0"
        iyy="0.0" iyz="0.0"
        izz="0.0"/>
    </inertial>
  </link>

  <link name="left_leg">
    <collision name="collision">
      <origin xyz="0 0 0" rpy="0 0 0"/>
      <geometry>
        <mesh filename="left_leg.stl" scale="0.01 0.01 0.01" name="left_leg" />
      </geometry>
    </collision>
    <visual name="left_leg_visual">
      <origin xyz="0 0 0" rpy="0 0 0"/>
      <geometry>
        <mesh filename="left_leg.stl" scale="0.01 0.01 0.01" name="left_leg" />
      </geometry>
      <material name="leg">
      </material>
    </visual>
    <inertial>
      <origin xyz="0 0 0" rpy="0 0 0"/>
      <mass value="0.1"/>
      <inertia
        ixx="0.0" ixy="0.0" ixz="0.0"
        iyy="0.0" iyz="0.0"
        izz="0.0"/>
    </inertial>
  </link>

  <link name="right_lower_leg">
    <collision name="collision">
      <origin xyz="0 0 0" rpy="0 0 0"/>
      <geometry>
        <mesh filename="right_lower_leg.stl" scale="0.01 0.01 0.01" name="right_lower_leg" />
      </geometry>
    </collision>
    <visual name="right_lower_leg_visual">
      <origin xyz="0 0 0" rpy="0 0 0"/>
      <geometry>
        <mesh filename="right_lower_leg.stl" scale="0.01 0.01 0.01" name="right_lower_leg" />
      </geometry>
      <material name="lower_leg">
        <color rgba="0.8 0.8 0.2 0.8"/>
      </material>
    </visual>
    <inertial>
      <origin xyz="0 0 0" rpy="0 0 0"/>
      <mass value="0.1"/>
      <inertia
        ixx="0.0" ixy="0.0" ixz="0.0"
        iyy="0.0" iyz="0.0"
        izz="0.0"/>
    </inertial>
  </link>

  <link name="left_lower_leg">
    <collision name="collision">
      <origin xyz="0 0 0" rpy="0 0 0"/>
      <geometry>
        <mesh filename="left_lower_leg.stl" scale="0.01 0.01 0.01" name="left_lower_leg" />
      </geometry>
    </collision>
    <visual name="left_leg_visual">
      <origin xyz="0 0 0" rpy="0 0 0"/>
      <geometry>
        <mesh filename="left_lower_leg.stl" scale="0.01 0.01 0.01" name="left_lower_leg" />
      </geometry>
      <material name="lower_leg">
      </material>
    </visual>
    <inertial>
      <origin xyz="0 0 0" rpy="0 0 0"/>
      <mass value="0.1"/>
      <inertia
        ixx="0.0" ixy="0.0" ixz="0.0"
        iyy="0.0" iyz="0.0"
        izz="0.0"/>
    </inertial>
  </link>


  <joint type="continuous" name="left_motor_joint">
    <origin xyz="0 0 0" rpy="0 0 0"/>
    <parent link="chassis"/>
    <child link="left_motor"/>
    <axis xyz="0 1 0" rpy="0 0 0"/>
    <limit effort="10" velocity="10"/>
    <joint_properties damping="0.5" friction="0.5"/>
  </joint>

  <joint type="continuous" name="right_motor_joint">
    <origin xyz="0 0 0" rpy="0 0 0"/>
    <parent link="chassis"/>
    <child link="right_motor"/>
    <axis xyz="0 1 0" rpy="0 0 0"/>
    <limit effort="10" velocity="10"/>
    <joint_properties damping="0.5" friction="0.5"/>
  </joint>

  <joint type="continuous" name="left_hip_joint">
    <origin xyz="0 0 0" rpy="0 0 0"/>
    <parent link="chassis"/>
    <child link="left_leg"/>
    <axis xyz="0 1 0" rpy="0 0 0"/>
    <limit effort="10" velocity="10"/>
    <joint_properties damping="0.5" friction="0.5"/>
  </joint>

  <joint type="continuous" name="right_hip_joint">
    <origin xyz="0 0 0" rpy="0 0 0"/>
    <parent link="chassis"/>
    <child link="right_leg"/>
    <axis xyz="0 1 0" rpy="0 0 0"/>
    <limit effort="10" velocity="10"/>
    <joint_properties damping="0.5" friction="0.5"/>
  </joint>

  <joint type="continuous" name="left_knee_joint">
    <origin xyz="0 0 0" rpy="0 0 0"/>
    <parent link="left_leg"/>
    <child link="left_lower_leg"/>
    <axis xyz="0 1 0" rpy="0 0 0"/>
    <limit effort="10" velocity="10"/>
    <joint_properties damping="0.5" friction="0.5"/>
  </joint>

  <joint type="continuous" name="right_knee_joint">
    <origin xyz="0 0 0" rpy="0 0 0"/>
    <parent link="right_leg"/>
    <child link="right_lower_leg"/>
    <axis xyz="0 1 0" rpy="0 0 0"/>
    <limit effort="10" velocity="10"/>
    <joint_properties damping="0.5" friction="0.5"/>
  </joint>

  <joint type="continuous" name="left_foot_joint">
    <origin xyz="0 0 0" rpy="0 0 0"/>
    <parent link="left_lower_leg"/>
    <child link="left_foot"/>
    <axis xyz="0 1 0" rpy="0 0 0"/>
    <limit effort="10" velocity="10"/>
    <joint_properties damping="0.5" friction="0.5"/>
  </joint>

  <joint type="continuous" name="right_foot_joint">
    <origin xyz="0 0 0" rpy="0 0 0"/>
    <parent link="right_lower_leg"/>
    <child link="right_foot"/>
    <axis xyz="0 1 0" rpy="0 0 0"/>
    <limit effort="10" velocity="10"/>
    <joint_properties damping="0.5" friction="0.5"/>
  </joint>

</robot>

